Traceback (most recent call last):
  File "inference2.py", line 22, in <module>
    import resampy
  File "/home/pi/.local/lib/python3.7/site-packages/resampy/__init__.py", line 6, in <module>
    from . import filters
  File "/home/pi/.local/lib/python3.7/site-packages/resampy/filters.py", line 29, in <module>
    import scipy.signal
  File "/home/pi/.local/lib/python3.7/site-packages/scipy/signal/__init__.py", line 301, in <module>
    from .ltisys import *
  File "/home/pi/.local/lib/python3.7/site-packages/scipy/signal/ltisys.py", line 31, in <module>
    from scipy import integrate, interpolate, linalg
  File "/home/pi/.local/lib/python3.7/site-packages/scipy/interpolate/__init__.py", line 167, in <module>
    from .interpolate import *
  File "/home/pi/.local/lib/python3.7/site-packages/scipy/interpolate/interpolate.py", line 24, in <module>
    from . import _ppoly
  File "<frozen importlib._bootstrap>", line 416, in parent
KeyboardInterrupt
2019-12-10 03:32:07.732925: E tensorflow/core/platform/hadoop/hadoop_file_system.cc:132] HadoopFileSystem load error: libhdfs.so: cannot open shared object file: No such file or directory
Traceback (most recent call last):
  File "inference2.py", line 69, in <module>
    main(sys.argv[1:])
  File "inference2.py", line 37, in main
    myrecording = sd.rec(int(seconds * sr), samplerate=sr, channels=1, dtype=np.int16)
  File "/home/pi/.local/lib/python3.7/site-packages/sounddevice.py", line 280, in rec
    ctx.input_dtype, callback, blocking, **kwargs)
  File "/home/pi/.local/lib/python3.7/site-packages/sounddevice.py", line 2498, in start_stream
    **kwargs)
  File "/home/pi/.local/lib/python3.7/site-packages/sounddevice.py", line 1382, in __init__
    **_remove_self(locals()))
  File "/home/pi/.local/lib/python3.7/site-packages/sounddevice.py", line 778, in __init__
    extra_settings, samplerate)
  File "/home/pi/.local/lib/python3.7/site-packages/sounddevice.py", line 2571, in _get_stream_parameters
    info = query_devices(device)
  File "/home/pi/.local/lib/python3.7/site-packages/sounddevice.py", line 569, in query_devices
    raise PortAudioError('Error querying device {0}'.format(device))
sounddevice.PortAudioError: Error querying device -1
2019-12-10 03:33:25.707443: E tensorflow/core/platform/hadoop/hadoop_file_system.cc:132] HadoopFileSystem load error: libhdfs.so: cannot open shared object file: No such file or directory
Traceback (most recent call last):
  File "inference2.py", line 69, in <module>
    main(sys.argv[1:])
  File "inference2.py", line 37, in main
    myrecording = sd.rec(int(seconds * sr), samplerate=sr, channels=1, dtype=np.int16)
  File "/home/pi/.local/lib/python3.7/site-packages/sounddevice.py", line 280, in rec
    ctx.input_dtype, callback, blocking, **kwargs)
  File "/home/pi/.local/lib/python3.7/site-packages/sounddevice.py", line 2498, in start_stream
    **kwargs)
  File "/home/pi/.local/lib/python3.7/site-packages/sounddevice.py", line 1382, in __init__
    **_remove_self(locals()))
  File "/home/pi/.local/lib/python3.7/site-packages/sounddevice.py", line 778, in __init__
    extra_settings, samplerate)
  File "/home/pi/.local/lib/python3.7/site-packages/sounddevice.py", line 2571, in _get_stream_parameters
    info = query_devices(device)
  File "/home/pi/.local/lib/python3.7/site-packages/sounddevice.py", line 569, in query_devices
    raise PortAudioError('Error querying device {0}'.format(device))
sounddevice.PortAudioError: Error querying device -1
